//The answer is: no, it wonâ€™t:

new Promise(function(resolve, reject) {
  setTimeout(() => {
    throw new Error("Whoops!");
  }, 1000);
}).catch(alert);
